Workbook

Sheet Start Here
C2: Synthetic value creation and returns model
C3: All company names, people roles, operating data, targets, and results are synthetic or illustrative. USD millions unless stated. No realized value is claimed.
C6: NimbleBridge Services (synthetic)
C8: Purpose | D8: Explore how a small set of operating initiatives could affect EBITDA, cash generation, debt paydown, and sponsor returns over a five-year ownership period.
C10: Open Dashboard first. Select a scenario on Controls. Change initiative toggles or assumptions in the yellow cells. Review formula steps on the build tabs and PASS/FAIL checks at the end.
C12: Workbook navigation | F12: Input and formula legend
C13: Dashboard | F13: Editable input | G13: Blue font and pale yellow fill
C14: Controls | F14: Same-sheet formula | G14: Black font
C15: Historical & Baseline | F15: Linked formula | G15: Green font
C16: Initiatives | F16: Check | G16: Green PASS or red FAIL
C17: Operating Model
C18: Cash Flow & Debt
C19: Returns
C20: Sensitivity
C21: VCP Tracker
C22: Checks & Definitions
C25: Scenario changes operating growth, margin, initiative adoption, timing, realization, implementation costs, and exit multiple. The active forecast uses one selector and one calculation engine.

Sheet Dashboard
C2: Value creation plan and sponsor returns
C3: NimbleBridge Services (synthetic). All values and plan tracking are illustrative. Selected scenario results update from workbook controls.
C5: Selected case | D5: =Controls!D6 -> Base
C7: Return snapshot
C8: Entry EBITDA ($m) | D8: =Returns!D11 -> 14
C9: Entry enterprise value ($m) | D9: =Returns!D13 -> 140
C10: Sponsor equity at entry ($m) | D10: =Returns!D16 -> 86.8
C11: Exit EBITDA ($m) | D11: =Returns!D18 -> 22.758631
C12: Exit enterprise value ($m) | D12: =Returns!D20 -> 227.58631
C13: Exit net debt ($m) | D13: ='Cash Flow & Debt'!H24 -> 15.216317
C14: Sponsor MOIC | D14: =Returns!D25 -> 2.4204393
C15: Sponsor IRR | D15: =Returns!D26 -> 0.19326469
C18: EBITDA bridge, FY2025 baseline to FY2030 exit
C19: FY2025 baseline EBITDA ($m) | D19: ='Historical & Baseline'!F8 -> 14
C20: Core revenue and margin change ($m) | D20: ='Operating Model'!H11-'Historical & Baseline'!F8 -> 5.8353388
C21: Pricing and mix contribution ($m) | D21: ='Operating Model'!H17 -> 1.39
C22: Commercial efficiency contribution ($m) | D22: ='Operating Model'!H23 -> 1.35
C23: AI finance automation contribution ($m) | D23: ='Operating Model'!H32 -> 0.183292
C24: FY2030 exit EBITDA ($m) | D24: ='Operating Model'!H35 -> 22.758631
C27: Enterprise value bridge at entry multiple
C28: Entry enterprise value ($m) | D28: =Returns!D13 -> 140
C29: EBITDA change at entry multiple ($m) | D29: =(Returns!D18-Returns!D11)*Returns!D12 -> 87.586308
C30: Exit multiple change ($m) | D30: =Returns!D18*(Returns!D19-Returns!D12) -> 0
C31: Exit enterprise value ($m) | D31: =SUM(D28:D30) -> 227.58631
C34: Operating trend
D35: 2023 | E35: 2024 | F35: 2025 | G35: 2026 | H35: 2027 | I35: 2028 | J35: 2029 | K35: 2030
C36: Revenue ($m) | D36: ='Historical & Baseline'!D7 -> 80 | E36: ='Historical & Baseline'!E7 -> 90 | F36: ='Historical & Baseline'!F7 -> 100 | G36: ='Operating Model'!D9 -> 106 | H36: ='Operating Model'!E9 -> 112.36 | I36: ='Operating Model'!F9 -> 118.5398 | J36: ='Operating Model'!G9 -> 124.46679 | K36: ='Operating Model'!H9 -> 130.0678
C37: EBITDA ($m) | D37: ='Historical & Baseline'!D8 -> 10 | E37: ='Historical & Baseline'!E8 -> 12.2 | F37: ='Historical & Baseline'!F8 -> 14 | G37: ='Operating Model'!D35 -> 14.13097 | H37: ='Operating Model'!E35 -> 18.022434 | I37: ='Operating Model'!F35 -> 19.925531 | J37: ='Operating Model'!G35 -> 21.500017 | K37: ='Operating Model'!H35 -> 22.758631
C40: Value plan tracker summary
C41: Quarterly initiative records | D41: =COUNTA('VCP Tracker'!C8:C67) -> 60
C42: Green RAG records | D42: =COUNTIF('VCP Tracker'!J8:J67,"Green") -> 45
C43: Amber RAG records | D43: =COUNTIF('VCP Tracker'!J8:J67,"Amber") -> 15
C44: Red RAG records | D44: =COUNTIF('VCP Tracker'!J8:J67,"Red") -> 0
C45: AI expand-gate records | D45: =COUNTIF('VCP Tracker'!L8:L67,"Expand") -> 6
C48: Selected-case sensitivities
C49: MOIC by exit EBITDA and multiple
C50: MOIC by AI realization and exit multiple | D50: =Sensitivity!D10 -> 1.5898017 | E50: =Sensitivity!E10 -> 1.8104398 | F50: =Sensitivity!F10 -> 2.0310779 | G50: =Sensitivity!G10 -> 2.251716 | H50: =Sensitivity!H10 -> 2.4723541
D51: =Sensitivity!D23 -> 1.8753227 | E51: =Sensitivity!E23 -> 1.8901616 | F51: =Sensitivity!F23 -> 1.9012908 | G51: =Sensitivity!G23 -> 1.9124199 | H51: =Sensitivity!H23 -> 1.9272588
D52: =Sensitivity!D24 -> 2.132543 | E52: =Sensitivity!E24 -> 2.148727 | F52: =Sensitivity!F24 -> 2.160865 | G52: =Sensitivity!G24 -> 2.173003 | H52: =Sensitivity!H24 -> 2.189187
D53: =Sensitivity!D25 -> 2.3897633 | E53: =Sensitivity!E25 -> 2.4072924 | F53: =Sensitivity!F25 -> 2.4204393 | G53: =Sensitivity!G25 -> 2.4335861 | H53: =Sensitivity!H25 -> 2.4511152
...

Sheet Controls
C2: Scenario and model controls
C3: All values shown are synthetic assumptions. Change blue-font yellow cells. Currency: USD millions except per-hour cost, hours, and unit conversion.
C5: Active case and initiative toggles
C6: Selected case | D6: Base
C8: Pricing and mix | D8: On
C9: Commercial efficiency | D9: On
C10: AI finance automation | D10: On
C13: Scenario assumptions
C14: Case | D14: Year 1 growth | E14: Year 2 growth | F14: Year 3 growth | G14: Year 4 growth | H14: Year 5 growth | I14: Annual core margin lift | J14: Exit multiple
C15: Base | D15: 0.06 | E15: 0.06 | F15: 0.055 | G15: 0.05 | H15: 0.045 | I15: 0.0025 | J15: 10
C16: Downside | D16: 0.015 | E16: 0.02 | F16: 0.025 | G16: 0.03 | H16: 0.03 | I16: 0 | J16: 8.5
C17: Upside | D17: 0.08 | E17: 0.075 | F17: 0.07 | G17: 0.06 | H17: 0.05 | I17: 0.004 | J17: 11
C20: Transaction, operating, and cash flow assumptions
C21: Entry EBITDA multiple | D21: 10
C22: Senior debt / entry EBITDA | D22: 4
C23: Entry transaction fees / entry EV | D23: 0.02
C24: Exit fees / exit EV | D24: 0.01
C25: Cash tax rate | D25: 0.25
C26: Cash interest rate on opening debt | D26: 0.09
C27: Depreciation / revenue | D27: 0.025
C28: Capital expenditure / revenue | D28: 0.03
C29: Working capital investment / revenue change | D29: 0.08
C30: Mandatory amortization / original debt | D30: 0.05
C31: Cash sweep / positive cash after mandatory amortization | D31: 0.75
C32: Dollars per USD million | D32: 1000000
... C35: Required return formula count | D35: 2
C36: Visible value-plan status thresholds
C37: Green variance threshold (actual less plan) | D37: -0.05
C38: Amber variance threshold (actual less plan) | D38: -0.15
C39: AI minimum adoption for expand gate | D39: 0.6
C40: AI minimum quality for expand gate | D40: 0.98
C41: AI gate interpretation | D41: Expand / Fix / Pause is a governance signal only; it does not change the forecast. If adoption and quality both fail, Pause takes precedence.
C42: Formula conventions | D42: Cash interest uses opening gross debt to avoid circularity. Excess cash is swept at the selected percentage and the remainder stays on balance sheet. No interim sponsor distributions are assumed.

Sheet Historical & Baseline
C2: Synthetic historical results and entry baseline
C3: Illustrative historical data only. The fictional company did not report these figures. USD millions.
D6: 2023 | E6: 2024 | F6: 2025
C7: Revenue ($m) | D7: 80 | E7: 90 | F7: 100
C8: EBITDA ($m) | D8: 10 | E8: 12.2 | F8: 14
C9: EBITDA margin | D9: =D8/D7 -> 0.125 | E9: =E8/E7 -> 0.13555556 | F9: =F8/F7 -> 0.14
C12: Entry baseline is FY2025 revenue and EBITDA. Forecast Year 1 begins in 2026.

Sheet Initiatives
C2: Initiative assumptions and execution ramp
C3: All initiative assumptions, roles, KPIs, dependencies, and outcomes are synthetic and illustrative. USD millions unless stated.
C5: Scenario rows feed the single active forecast. Ramp is the portion of full annual adoption/benefit reached in each ownership year.
C6: Initiative | D6: Scenario | E6: Start year | F6: Realization | G6: Implementation cost ($m) | H6: Annual run cost ($m) | I6: Confidence | J6: Dependency | K6: Year 1 ramp | L6: Year 2 ramp | M6: Year 3 ramp | N6: Year 4 ramp | O6: Year 5 ramp
C7: Pricing and mix | D7: Base | E7: 1 | F7: 0.8 | G7: 0.35 | H7: 0.05 | I7: 0.8 | J7: Renewal adoption and churn within guardrail | K7: 0.3 | L7: 0.65 | M7: 0.85 | N7: 0.95 | O7: 1
C8: Pricing and mix | D8: Downside | E8: 2 | F8: 0.55 | G8: 0.5 | H8: 0.07 | I8: 0.55 | J8: Renewal adoption and churn within guardrail | K8: 0 | L8: 0.25 | M8: 0.55 | N8: 0.75 | O8: 0.85
C9: Pricing and mix | D9: Upside | E9: 1 | F9: 0.9 | G9: 0.32 | H9: 0.04 | I9: 0.9 | J9: Renewal book and sales enablement | K9: 0.4 | L9: 0.75 | M9: 0.95 | N9: 1 | O9: 1
C14: Commercial efficiency | D14: Base | E14: 1 | F14: 0.75 | G14: 0.4 | H14: 0 | I14: 0.75 | J14: Spend baseline and accountable cost owners | K14: 0.25 | L14: 0.6 | M14: 0.85 | N14: 1 | O14: 1
C15: Commercial efficiency | D15: Downside | E15: 2 | F15: 0.55 | G15: 0.55 | H15: 0 | I15: 0.55 | J15: Validated savings and service levels | K15: 0 | L15: 0.25 | M15: 0.5 | N15: 0.7 | O15: 0.8
C16: Commercial efficiency | D16: Upside | E16: 1 | F16: 0.9 | G16: 0.35 | H16: 0 | I16: 0.9 | J16: Procurement and process-owner capacity | K16: 0.35 | L16: 0.75 | M16: 1 | N16: 1 | O16: 1
C21: AI finance automation | D21: Base | E21: 1 | F21: 0.65 | G21: 0.85 | H21: 0.2 | I21: 0.7 | J21: Data quality, adoption, and process controls | K21: 0.25 | L21: 0.55 | M21: 0.75 | N21: 0.85 | O21: 0.9
C22: AI finance automation | D22: Downside | E22: 2 | F22: 0.4 | G22: 0.95 | H22: 0.24 | I22: 0.4 | J22: Quality remediation before workflow expansion | K22: 0 | L22: 0.2 | M22: 0.35 | N22: 0.5 | O22: 0.6
C23: AI finance automation | D23: Upside | E23: 1 | F23: 0.8 | G23: 0.75 | H23: 0.18 | I23: 0.8 | J23: Pilot quality and finance-team adoption | K23: 0.35 | L23: 0.7 | M23: 0.9 | N23: 1 | O23: 1
C26: Initiative benefit basis
C27: Initiative | D27: Full annual gross contribution ($m) | E27: Churn offset ($m) | F27: Addressable hours | G27: Loaded cost ($/hour) | H27: Avoidable share | I27: KPI | J27: Owner role | K27: Interpretation
C28: Pricing and mix | D28: 2.4 | E28: 0.6 | F28: 0 | G28: 0 | H28: 0 | I28: Renewal adoption (%) | J28: Commercial workstream owner (synthetic role) | K28: Gross incremental contribution less churn offset; figures are synthetic.
C29: Commercial efficiency | D29: 1.8 | E29: 0 | F29: 0 | G29: 0 | H29: 0 | I29: Validated savings delivered (%) | J29: Operations workstream owner (synthetic role) | K29: Gross annual cost opportunity before realization; figures are synthetic.
C30: AI finance automation | D30: 0 | E30: 0 | F30: 18000 | G30: 52 | H30: 0.7 | I30: Eligible workflow adoption (%) | J30: Finance transformation owner (synthetic role) | K30: Hours released convert to EBITDA only through avoidable cost share and realization.
C33: Pricing benefit is incremental gross contribution after the displayed churn offset. Commercial savings are treated as EBITDA contributions. AI capacity is converted to avoided contractor or hiring cost only for the displayed avoidable share and realization rate; remaining hours are not valued as EBITDA.

Sheet Operating Model
C2: Operating model and EBITDA bridge
C3: Selected scenario links to Controls. Annual forecast in USD millions, except capacity hours. All inputs and outputs are synthetic or illustrative.
C5: Selected case | D5: =Controls!D6 -> Base
C6: Ownership year | D6: 1 | E6: 2 | F6: 3 | G6: 4 | H6: 5
C7: Core forecast
C8: Selected revenue growth | D8: =INDEX(Controls!$D$15:$H$17,MATCH(Controls!$D$6,Controls!$C$15:$C$17,0),D$6) -> 0.06 | E8: =INDEX(Controls!$D$15:$H$17,MATCH(Controls!$D$6,Controls!$C$15:$C$17,0),E$6) -> 0.06 | F8: =INDEX(Controls!$D$15:$H$17,MATCH(Controls!$D$6,Controls!$C$15:$C$17,0),F$6) -> 0.055 | G8: =INDEX(Controls!$D$15:$H$17,MATCH(Controls!$D$6,Controls!$C$15:$C$17,0),G$6) -> 0.05 | H8: =INDEX(Controls!$D$15:$H$17,MATCH(Controls!$D$6,Controls!$C$15:$C$17,0),H$6) -> 0.045
C9: Core revenue ($m) | D9: ='Historical & Baseline'!F7*(1+D8) -> 106 | E9: =D9*(1+E8) -> 112.36 | F9: =E9*(1+F8) -> 118.5398 | G9: =F9*(1+G8) -> 124.46679 | H9: =G9*(1+H8) -> 130.0678
C10: Core EBITDA margin | D10: ='Historical & Baseline'!F9+INDEX(Controls!$I$15:$I$17,MATCH(Controls!$D$6,Controls!$C$15:$C$17,0)) -> 0.1425 | E10: =D10+INDEX(Controls!$I$15:$I$17,MATCH(Controls!$D$6,Controls!$C$15:$C$17,0)) -> 0.145 | F10: =E10+INDEX(Controls!$I$15:$I$17,MATCH(Controls!$D$6,Controls!$C$15:$C$17,0)) -> 0.1475 | G10: =F10+INDEX(Controls!$I$15:$I$17,MATCH(Controls!$D$6,Controls!$C$15:$C$17,0)) -> 0.15 | H10: =G10+INDEX(Controls!$I$15:$I$17,MATCH(Controls!$D$6,Controls!$C$15:$C$17,0)) -> 0.1525
C11: Core EBITDA before initiatives ($m) | D11: =D9*D10 -> 15.105 | E11: =E9*E10 -> 16.2922 | F11: =F9*F10 -> 17.48462 | G11: =G9*G10 -> 18.670019 | H11: =H9*H10 -> 19.835339
C12: Pricing and mix
C13: Pricing detail
C14: Pricing ramp | D14: =IF(D$6>=INDEX(Initiatives!$E$7:$E$9,MATCH(Controls!$D$6,Initiatives!$D$7:$D$9,0)),INDEX(Initiatives!$K$7:$O$9,MATCH(Controls!$D$6,Initiatives!$D$7:$D$9,0),D$6),0) -> 0.3 | E14: =IF(E$6>=INDEX(Initiatives!$E$7:$E$9,MATCH(Controls!$D$6,Initiatives!$D$7:$D$9,0)),INDEX(Initiatives!$K$7:$O$9,MATCH(Controls!$D$6,Initiatives!$D$7:$D$9,0),E$6),0) -> 0.65 | F14: =IF(F$6>=INDEX(Initiatives!$E$7:$E$9,MATCH(Controls!$D$6,Initiatives!$D$7:$D$9,0)),INDEX(Initiatives!$K$7:$O$9,MATCH(Controls!$D$6,Initiatives!$D$7:$D$9,0),F$6),0) -> 0.85 | G14: =IF(G$6>=INDEX(Initiatives!$E$7:$E$9,MATCH(Controls!$D$6,Initiatives!$D$7:$D$9,0)),INDEX(Initiatives!$K$7:$O$9,MATCH(Controls!$D$6,Initiatives!$D$7:$D$9,0),G$6),0) -> 0.95 | H14: =IF(H$6>=INDEX(Initiatives!$E$7:$E$9,MATCH(Controls!$D$6,Initiatives!$D$7:$D$9,0)),INDEX(Initiatives!$K$7:$O$9,MATCH(Controls!$D$6,Initiatives!$D$7:$D$9,0),H$6),0) -> 1
C15: Pricing contribution before costs ($m) | D15: =IF(Controls!$D$8="On",(Initiatives!$D$28-Initiatives!$E$28)*D14*INDEX(Initiatives!$F$7:$F$9,MATCH(Controls!$D$6,Initiatives!$D$7:$D$9,0)),0) -> 0.432 | E15: =IF(Controls!$D$8="On",(Initiatives!$D$28-Initiatives!$E$28)*E14*INDEX(Initiatives!$F$7:$F$9,MATCH(Controls!$D$6,Initiatives!$D$7:$D$9,0)),0) -> 0.936 | F15: =IF(Controls!$D$8="On",(Initiatives!$D$28-Initiatives!$E$28)*F14*INDEX(Initiatives!$F$7:$F$9,MATCH(Controls!$D$6,Initiatives!$D$7:$D$9,0)),0) -> 1.224 | G15: =IF(Controls!$D$8="On",(Initiatives!$D$28-Initiatives!$E$28)*G14*INDEX(Initiatives!$F$7:$F$9,MATCH(Controls!$D$6,Initiatives!$D$7:$D$9,0)),0) -> 1.368 | H15: =IF(Controls!$D$8="On",(Initiatives!$D$28-Initiatives!$E$28)*H14*INDEX(Initiatives!$F$7:$F$9,MATCH(Controls!$D$6,Initiatives!$D$7:$D$9,0)),0) -> 1.44
C16: Pricing implementation and annual run costs ($m) | D16: =IF(AND(Controls!$D$8="On",D$6=INDEX(Initiatives!$E$7:$E$9,MATCH(Controls!$D$6,Initiatives!$D$7:$D$9,0))),INDEX(Initiatives!$G$7:$G$9,MATCH(Controls!$D$6,Initiatives!$D$7:$D$9,0)),0)+IF(AND(Controls!$D$8="On",D$6>=INDEX(Initiatives!$E$7:$E$9,MATCH(Controls!$D$6,Initiatives!$D$7:$D$9,0))),INDEX(Initiatives!$H$7:$H$9,MATCH(Controls!$D$6,Initiatives!$D$7:$D$9,0)),0) -> 0.4 | E16: =IF(AND(Controls!$D$8="On",E$6=INDEX(Initiatives!$E$7:$E$9,MATCH(Controls!$D$6,Initiatives!$D$7:$D$9,0))),INDEX(Initiatives!$G$7:$G$9,MATCH(Controls!$D$6,Initiatives!$D$7:$D$9,0)),0)+IF(AND(Controls!$D$8="On",E$6>=INDEX(Initiatives!$E$7:$E$9,MATCH(Controls!$D$6,Initiatives!$D$7:$D$9,0))),INDEX(Initiatives!$H$7:$H$9,MATCH(Controls!$D$6,Initiatives!$D$7:$D$9,0)),0) -> 0.05 | F16: =IF(AND(Controls!$D$8="On",F$6=INDEX(Initiatives!$E$7:$E$9,MATCH(Controls!$D$6,Initiatives!$D$7:$D$9,0))),INDEX(Initiatives!$G$7:$G$9,MATCH(Controls!$D$6,Initiatives!$D$7:$D$9,0)),0)+IF(AND(Controls!$D$8="On",F$6>=INDEX(Initiatives!$E$7:$E$9,MATCH(Controls!$D$6,Initiatives!$D$7:$D$9,0))),INDEX(Initiatives!$H$7:$H$9,MATCH(Controls!$D$6,Initiatives!$D$7:$D$9,0)),0) -> 0.05 | G16: =IF(AND(Controls!$D$8="On",G$6=INDEX(Initiatives!$E$7:$E$9,MATCH(Controls!$D$6,Initiatives!$D$7:$D$9,0))),INDEX(Initiatives!$G$7:$G$9,MATCH(Controls!$D$6,Initiatives!$D$7:$D$9,0)),0)+IF(AND(Controls!$D$8="On",G$6>=INDEX(Initiatives!$E$7:$E$9,MATCH(Controls!$D$6,Initiatives!$D$7:$D$9,0))),INDEX(Initiatives!$H$7:$H$9,MATCH(Controls!$D$6,Initiatives!$D$7:$D$9,0)),0) -> 0.05 | H16: =IF(AND(Controls!$D$8="On",H$6=INDEX(Initiatives!$E$7:$E$9,MATCH(Controls!$D$6,Initiatives!$D$7:$D$9,0))),INDEX(Initiatives!$G$7:$G$9,MATCH(Controls!$D$6,Initiatives!$D$7:$D$9,0)),0)+IF(AND(Controls!$D$8="On",H$6>=INDEX(Initiatives!$E$7:$E$9,MATCH(Controls!$D$6,Initiatives!$D$7:$D$9,0))),INDEX(Initiatives!$H$7:$H$9,MATCH(Controls!$D$6,Initiatives!$D$7:$D$9,0)),0) -> 0.05
C17: Pricing and mix net EBITDA contribution ($m) | D17: =D15-D16 -> 0.032 | E17: =E15-E16 -> 0.886 | F17: =F15-F16 -> 1.174 | G17: =G15-G16 -> 1.318 | H17: =H15-H16 -> 1.39
C18: Commercial efficiency
C19: Commercial detail
C20: Commercial efficiency ramp | D20: =IF(D$6>=INDEX(Initiatives!$E$14:$E$16,MATCH(Controls!$D$6,Initiatives!$D$14:$D$16,0)),INDEX(Initiatives!$K$14:$O$16,MATCH(Controls!$D$6,Initiatives!$D$14:$D$16,0),D$6),0) -> 0.25 | E20: =IF(E$6>=INDEX(Initiatives!$E$14:$E$16,MATCH(Controls!$D$6,Initiatives!$D$14:$D$16,0)),INDEX(Initiatives!$K$14:$O$16,MATCH(Controls!$D$6,Initiatives!$D$14:$D$16,0),E$6),0) -> 0.6 | F20: =IF(F$6>=INDEX(Initiatives!$E$14:$E$16,MATCH(Controls!$D$6,Initiatives!$D$14:$D$16,0)),INDEX(Initiatives!$K$14:$O$16,MATCH(Controls!$D$6,Initiatives!$D$14:$D$16,0),F$6),0) -> 0.85 | G20: =IF(G$6>=INDEX(Initiatives!$E$14:$E$16,MATCH(Controls!$D$6,Initiatives!$D$14:$D$16,0)),INDEX(Initiatives!$K$14:$O$16,MATCH(Controls!$D$6,Initiatives!$D$14:$D$16,0),G$6),0) -> 1 | H20: =IF(H$6>=INDEX(Initiatives!$E$14:$E$16,MATCH(Controls!$D$6,Initiatives!$D$14:$D$16,0)),INDEX(Initiatives!$K$14:$O$16,MATCH(Controls!$D$6,Initiatives!$D$14:$D$16,0),H$6),0) -> 1
C21: Commercial efficiency gross savings ($m) | D21: =IF(Controls!$D$9="On",Initiatives!$D$29*D20*INDEX(Initiatives!$F$14:$F$16,MATCH(Controls!$D$6,Initiatives!$D$14:$D$16,0)),0) -> 0.3375 | E21: =IF(Controls!$D$9="On",Initiatives!$D$29*E20*INDEX(Initiatives!$F$14:$F$16,MATCH(Controls!$D$6,Initiatives!$D$14:$D$16,0)),0) -> 0.81 | F21: =IF(Controls!$D$9="On",Initiatives!$D$29*F20*INDEX(Initiatives!$F$14:$F$16,MATCH(Controls!$D$6,Initiatives!$D$14:$D$16,0)),0) -> 1.1475 | G21: =IF(Controls!$D$9="On",Initiatives!$D$29*G20*INDEX(Initiatives!$F$14:$F$16,MATCH(Controls!$D$6,Initiatives!$D$14:$D$16,0)),0) -> 1.35 | H21: =IF(Controls!$D$9="On",Initiatives!$D$29*H20*INDEX(Initiatives!$F$14:$F$16,MATCH(Controls!$D$6,Initiatives!$D$14:$D$16,0)),0) -> 1.35
C22: Commercial implementation and annual run costs ($m) | D22: =IF(AND(Controls!$D$9="On",D$6=INDEX(Initiatives!$E$14:$E$16,MATCH(Controls!$D$6,Initiatives!$D$14:$D$16,0))),INDEX(Initiatives!$G$14:$G$16,MATCH(Controls!$D$6,Initiatives!$D$14:$D$16,0)),0)+IF(AND(Controls!$D$9="On",D$6>=INDEX(Initiatives!$E$14:$E$16,MATCH(Controls!$D$6,Initiatives!$D$14:$D$16,0))),INDEX(Initiatives!$H$14:$H$16,MATCH(Controls!$D$6,Initiatives!$D$14:$D$16,0)),0) -> 0.4 | E22: =IF(AND(Controls!$D$9="On",E$6=INDEX(Initiatives!$E$14:$E$16,MATCH(Controls!$D$6,Initiatives!$D$14:$D$16,0))),INDEX(Initiatives!$G$14:$G$16,MATCH(Controls!$D$6,Initiatives!$D$14:$D$16,0)),0)+IF(AND(Controls!$D$9="On",E$6>=INDEX(Initiatives!$E$14:$E$16,MATCH(Controls!$D$6,Initiatives!$D$14:$D$16,0))),INDEX(Initiatives!$H$14:$H$16,MATCH(Controls!$D$6,Initiatives!$D$14:$D$16,0)),0) -> 0 | F22: =IF(AND(Controls!$D$9="On",F$6=INDEX(Initiatives!$E$14:$E$16,MATCH(Controls!$D$6,Initiatives!$D$14:$D$16,0))),INDEX(Initiatives!$G$14:$G$16,MATCH(Controls!$D$6,Initiatives!$D$14:$D$16,0)),0)+IF(AND(Controls!$D$9="On",F$6>=INDEX(Initiatives!$E$14:$E$16,MATCH(Controls!$D$6,Initiatives!$D$14:$D$16,0))),INDEX(Initiatives!$H$14:$H$16,MATCH(Controls!$D$6,Initiatives!$D$14:$D$16,0)),0) -> 0 | G22: =IF(AND(Controls!$D$9="On",G$6=INDEX(Initiatives!$E$14:$E$16,MATCH(Controls!$D$6,Initiatives!$D$14:$D$16,0))),INDEX(Initiatives!$G$14:$G$16,MATCH(Controls!$D$6,Initiatives!$D$14:$D$16,0)),0)+IF(AND(Controls!$D$9="On",G$6>=INDEX(Initiatives!$E$14:$E$16,MATCH(Controls!$D$6,Initiatives!$D$14:$D$16,0))),INDEX(Initiatives!$H$14:$H$16,MATCH(Controls!$D$6,Initiatives!$D$14:$D$16,0)),0) -> 0 | H22: =IF(AND(Controls!$D$9="On",H$6=INDEX(Initiatives!$E$14:$E$16,MATCH(Controls!$D$6,Initiatives!$D$14:$D$16,0))),INDEX(Initiatives!$G$14:$G$16,MATCH(Controls!$D$6,Initiatives!$D$14:$D$16,0)),0)+IF(AND(Controls!$D$9="On",H$6>=INDEX(Initiatives!$E$14:$E$16,MATCH(Controls!$D$6,Initiatives!$D$14:$D$16,0))),INDEX(Initiatives!$H$14:$H$16,MATCH(Controls!$D$6,Initiatives!$D$14:$D$16,0)),0) -> 0
C23: Commercial efficiency net EBITDA contribution ($m) | D23: =D21-D22 -> -0.0625 | E23: =E21-E22 -> 0.81 | F23: =F21-F22 -> 1.1475 | G23: =G21-G22 -> 1.35 | H23: =H21-H22 -> 1.35
C24: AI finance automation
C25: AI capacity and benefit
C26: AI workflow adoption ramp | D26: =IF(D$6>=INDEX(Initiatives!$E$21:$E$23,MATCH(Controls!$D$6,Initiatives!$D$21:$D$23,0)),INDEX(Initiatives!$K$21:$O$23,MATCH(Controls!$D$6,Initiatives!$D$21:$D$23,0),D$6),0) -> 0.25 | E26: =IF(E$6>=INDEX(Initiatives!$E$21:$E$23,MATCH(Controls!$D$6,Initiatives!$D$21:$D$23,0)),INDEX(Initiatives!$K$21:$O$23,MATCH(Controls!$D$6,Initiatives!$D$21:$D$23,0),E$6),0) -> 0.55 | F26: =IF(F$6>=INDEX(Initiatives!$E$21:$E$23,MATCH(Controls!$D$6,Initiatives!$D$21:$D$23,0)),INDEX(Initiatives!$K$21:$O$23,MATCH(Controls!$D$6,Initiatives!$D$21:$D$23,0),F$6),0) -> 0.75 | G26: =IF(G$6>=INDEX(Initiatives!$E$21:$E$23,MATCH(Controls!$D$6,Initiatives!$D$21:$D$23,0)),INDEX(Initiatives!$K$21:$O$23,MATCH(Controls!$D$6,Initiatives!$D$21:$D$23,0),G$6),0) -> 0.85 | H26: =IF(H$6>=INDEX(Initiatives!$E$21:$E$23,MATCH(Controls!$D$6,Initiatives!$D$21:$D$23,0)),INDEX(Initiatives!$K$21:$O$23,MATCH(Controls!$D$6,Initiatives!$D$21:$D$23,0),H$6),0) -> 0.9
C27: AI capacity released (hours) | D27: =IF(Controls!$D$10="On",Initiatives!$F$30*D26,0) -> 4500 | E27: =IF(Controls!$D$10="On",Initiatives!$F$30*E26,0) -> 9900 | F27: =IF(Controls!$D$10="On",Initiatives!$F$30*F26,0) -> 13500 | G27: =IF(Controls!$D$10="On",Initiatives!$F$30*G26,0) -> 15300 | H27: =IF(Controls!$D$10="On",Initiatives!$F$30*H26,0) -> 16200
C28: AI cost value before realization ($m) | D28: =D27*Initiatives!$G$30*Initiatives!$H$30/Controls!$D$32 -> 0.1638 | E28: =E27*Initiatives!$G$30*Initiatives!$H$30/Controls!$D$32 -> 0.36036 | F28: =F27*Initiatives!$G$30*Initiatives!$H$30/Controls!$D$32 -> 0.4914 | G28: =G27*Initiatives!$G$30*Initiatives!$H$30/Controls!$D$32 -> 0.55692 | H28: =H27*Initiatives!$G$30*Initiatives!$H$30/Controls!$D$32 -> 0.58968
C29: AI avoided-cost savings after realization ($m) | D29: =IF(Controls!$D$10="On",D28*INDEX(Initiatives!$F$21:$F$23,MATCH(Controls!$D$6,Initiatives!$D$21:$D$23,0)),0) -> 0.10647 | E29: =IF(Controls!$D$10="On",E28*INDEX(Initiatives!$F$21:$F$23,MATCH(Controls!$D$6,Initiatives!$D$21:$D$23,0)),0) -> 0.234234 | F29: =IF(Controls!$D$10="On",F28*INDEX(Initiatives!$F$21:$F$23,MATCH(Controls!$D$6,Initiatives!$D$21:$D$23,0)),0) -> 0.31941 | G29: =IF(Controls!$D$10="On",G28*INDEX(Initiatives!$F$21:$F$23,MATCH(Controls!$D$6,Initiatives!$D$21:$D$23,0)),0) -> 0.361998 | H29: =IF(Controls!$D$10="On",H28*INDEX(Initiatives!$F$21:$F$23,MATCH(Controls!$D$6,Initiatives!$D$21:$D$23,0)),0) -> 0.383292
C30: AI implementation cost ($m) | D30: =IF(AND(Controls!$D$10="On",D$6=INDEX(Initiatives!$E$21:$E$23,MATCH(Controls!$D$6,Initiatives!$D$21:$D$23,0))),INDEX(Initiatives!$G$21:$G$23,MATCH(Controls!$D$6,Initiatives!$D$21:$D$23,0)),0) -> 0.85 | E30: =IF(AND(Controls!$D$10="On",E$6=INDEX(Initiatives!$E$21:$E$23,MATCH(Controls!$D$6,Initiatives!$D$21:$D$23,0))),INDEX(Initiatives!$G$21:$G$23,MATCH(Controls!$D$6,Initiatives!$D$21:$D$23,0)),0) -> 0 | F30: =IF(AND(Controls!$D$10="On",F$6=INDEX(Initiatives!$E$21:$E$23,MATCH(Controls!$D$6,Initiatives!$D$21:$D$23,0))),INDEX(Initiatives!$G$21:$G$23,MATCH(Controls!$D$6,Initiatives!$D$21:$D$23,0)),0) -> 0 | G30: =IF(AND(Controls!$D$10="On",G$6=INDEX(Initiatives!$E$21:$E$23,MATCH(Controls!$D$6,Initiatives!$D$21:$D$23,0))),INDEX(Initiatives!$G$21:$G$23,MATCH(Controls!$D$6,Initiatives!$D$21:$D$23,0)),0) -> 0 | H30: =IF(AND(Controls!$D$10="On",H$6=INDEX(Initiatives!$E$21:$E$23,MATCH(Controls!$D$6,Initiatives!$D$21:$D$23,0))),INDEX(Initiatives!$G$21:$G$23,MATCH(Controls!$D$6,Initiatives!$D$21:$D$23,0)),0) -> 0
C31: AI annual run cost ($m) | D31: =IF(AND(Controls!$D$10="On",D$6>=INDEX(Initiatives!$E$21:$E$23,MATCH(Controls!$D$6,Initiatives!$D$21:$D$23,0))),INDEX(Initiatives!$H$21:$H$23,MATCH(Controls!$D$6,Initiatives!$D$21:$D$23,0)),0) -> 0.2 | E31: =IF(AND(Controls!$D$10="On",E$6>=INDEX(Initiatives!$E$21:$E$23,MATCH(Controls!$D$6,Initiatives!$D$21:$D$23,0))),INDEX(Initiatives!$H$21:$H$23,MATCH(Controls!$D$6,Initiatives!$D$21:$D$23,0)),0) -> 0.2 | F31: =IF(AND(Controls!$D$10="On",F$6>=INDEX(Initiatives!$E$21:$E$23,MATCH(Controls!$D$6,Initiatives!$D$21:$D$23,0))),INDEX(Initiatives!$H$21:$H$23,MATCH(Controls!$D$6,Initiatives!$D$21:$D$23,0)),0) -> 0.2 | G31: =IF(AND(Controls!$D$10="On",G$6>=INDEX(Initiatives!$E$21:$E$23,MATCH(Controls!$D$6,Initiatives!$D$21:$D$23,0))),INDEX(Initiatives!$H$21:$H$23,MATCH(Controls!$D$6,Initiatives!$D$21:$D$23,0)),0) -> 0.2 | H31: =IF(AND(Controls!$D$10="On",H$6>=INDEX(Initiatives!$E$21:$E$23,MATCH(Controls!$D$6,Initiatives!$D$21:$D$23,0))),INDEX(Initiatives!$H$21:$H$23,MATCH(Controls!$D$6,Initiatives!$D$21:$D$23,0)),0) -> 0.2
C32: AI finance automation net EBITDA contribution ($m) | D32: =D29-D30-D31 -> -0.94353 | E32: =E29-E30-E31 -> 0.034234 | F32: =F29-F30-F31 -> 0.11941 | G32: =G29-G30-G31 -> 0.161998 | H32: =H29-H30-H31 -> 0.183292
C33: Consolidated EBITDA
C34: Net initiative contribution ($m) | D34: =SUM(D17,D23,D32) -> -0.97403 | E34: =SUM(E17,E23,E32) -> 1.730234 | F34: =SUM(F17,F23,F32) -> 2.44091 | G34: =SUM(G17,G23,G32) -> 2.829998 | H34: =SUM(H17,H23,H32) -> 2.923292
C35: Total EBITDA ($m) | D35: =D11+D34 -> 14.13097 | E35: =E11+E34 -> 18.022434 | F35: =F11+F34 -> 19.925531 | G35: =G11+G34 -> 21.500017 | H35: =H11+H34 -> 22.758631
C36: Total EBITDA margin | D36: =D35/D9 -> 0.13331104 | E36: =E35/E9 -> 0.16039902 | F36: =F35/F9 -> 0.16809148 | G36: =G35/G9 -> 0.17273697 | H36: =H35/H9 -> 0.17497514

Sheet Cash Flow & Debt
C2: Cash flow, debt paydown, and retained cash
C3: Selected scenario, annual periods, USD millions. Interest is calculated on opening gross debt to avoid circular formulas. All figures are synthetic.
C5: Selected case | D5: =Controls!D6 -> Base
D6: 1 | E6: 2 | F6: 3 | G6: 4 | H6: 5
C8: Total EBITDA ($m) | D8: ='Operating Model'!D35 -> 14.13097 | E8: ='Operating Model'!E35 -> 18.022434 | F8: ='Operating Model'!F35 -> 19.925531 | G8: ='Operating Model'!G35 -> 21.500017 | H8: ='Operating Model'!H35 -> 22.758631
C9: Depreciation ($m) | D9: ='Operating Model'!D9*Controls!$D$27 -> 2.65 | E9: ='Operating Model'!E9*Controls!$D$27 -> 2.809 | F9: ='Operating Model'!F9*Controls!$D$27 -> 2.963495 | G9: ='Operating Model'!G9*Controls!$D$27 -> 3.1116697 | H9: ='Operating Model'!H9*Controls!$D$27 -> 3.2516949
C10: EBIT ($m) | D10: =D8-D9 -> 11.48097 | E10: =E8-E9 -> 15.213434 | F10: =F8-F9 -> 16.962035 | G10: =G8-G9 -> 18.388347 | H10: =H8-H9 -> 19.506936
C11: Opening gross debt ($m) | D11: =Returns!$D$15 -> 56 | E11: =D22 -> 52.434454 | F11: =E22 -> 46.442956 | G11: =F22 -> 38.570423 | H11: =G22 -> 29.033842
C12: Cash interest ($m) | D12: =D11*Controls!$D$26 -> 5.04 | E12: =E11*Controls!$D$26 -> 4.7191009 | F12: =F11*Controls!$D$26 -> 4.179866 | G12: =G11*Controls!$D$26 -> 3.4713381 | H12: =H11*Controls!$D$26 -> 2.6130458
C13: Taxable earnings after interest ($m) | D13: =MAX(0,D10-D12) -> 6.44097 | E13: =MAX(0,E10-E12) -> 10.494333 | F13: =MAX(0,F10-F12) -> 12.782169 | G13: =MAX(0,G10-G12) -> 14.917009 | H13: =MAX(0,H10-H12) -> 16.89389
C14: Cash tax ($m) | D14: =D13*Controls!$D$25 -> 1.6102425 | E14: =E13*Controls!$D$25 -> 2.6235833 | F14: =F13*Controls!$D$25 -> 3.1955424 | G14: =G13*Controls!$D$25 -> 3.7292522 | H14: =H13*Controls!$D$25 -> 4.2234725
C15: Capital expenditure ($m) | D15: ='Operating Model'!D9*Controls!$D$28 -> 3.18 | E15: ='Operating Model'!E9*Controls!$D$28 -> 3.3708 | F15: ='Operating Model'!F9*Controls!$D$28 -> 3.556194 | G15: ='Operating Model'!G9*Controls!$D$28 -> 3.7340037 | H15: ='Operating Model'!H9*Controls!$D$28 -> 3.9020339
C16: Working capital investment ($m) | D16: =MAX(0,('Operating Model'!D9-'Historical & Baseline'!$F$7)*Controls!$D$29) -> 0.48 | E16: =MAX(0,('Operating Model'!E9-'Operating Model'!D9)*Controls!$D$29) -> 0.5088 | F16: =MAX(0,('Operating Model'!F9-'Operating Model'!E9)*Controls!$D$29) -> 0.494384 | G16: =MAX(0,('Operating Model'!G9-'Operating Model'!F9)*Controls!$D$29) -> 0.4741592 | H16: =MAX(0,('Operating Model'!H9-'Operating Model'!G9)*Controls!$D$29) -> 0.44808044
C17: Cash flow before debt service ($m) | D17: =D8-D14-D12-D15-D16 -> 3.8207275 | E17: =E8-E14-E12-E15-E16 -> 6.8001498 | F17: =F8-F14-F12-F15-F16 -> 8.4995441 | G17: =G8-G14-G12-G15-G16 -> 10.091263 | H17: =H8-H14-H12-H15-H16 -> 11.571998
C18: Opening cash ($m) | D18: =Controls!$D$33 -> 0 | E18: =D23 -> 0.25518188 | F18: =E23 -> 1.0638329 | G18: =F23 -> 1.6908443 | H18: =G23 -> 2.2455269
C19: Mandatory amortization ($m) | D19: =MIN(D11,Returns!$D$15*Controls!$D$30) -> 2.8 | E19: =MIN(E11,Returns!$D$15*Controls!$D$30) -> 2.8 | F19: =MIN(F11,Returns!$D$15*Controls!$D$30) -> 2.8 | G19: =MIN(G11,Returns!$D$15*Controls!$D$30) -> 2.8 | H19: =MIN(H11,Returns!$D$15*Controls!$D$30) -> 2.8
C20: Cash available after mandatory amortization ($m) | D20: =D18+D17-D19 -> 1.0207275 | E20: =E18+E17-E19 -> 4.2553317 | F20: =F18+F17-F19 -> 6.763377 | G20: =G18+G17-G19 -> 8.9821076 | H20: =H18+H17-H19 -> 11.017525
C21: Cash sweep ($m) | D21: =MIN(D11-D19,MAX(0,D20)*Controls!$D$31) -> 0.76554563 | E21: =MIN(E11-E19,MAX(0,E20)*Controls!$D$31) -> 3.1914988 | F21: =MIN(F11-F19,MAX(0,F20)*Controls!$D$31) -> 5.0725328 | G21: =MIN(G11-G19,MAX(0,G20)*Controls!$D$31) -> 6.7365807 | H21: =MIN(H11-H19,MAX(0,H20)*Controls!$D$31) -> 8.2631438
C22: Ending gross debt ($m) | D22: =D11-D19-D21 -> 52.434454 | E22: =E11-E19-E21 -> 46.442956 | F22: =F11-F19-F21 -> 38.570423 | G22: =G11-G19-G21 -> 29.033842 | H22: =H11-H19-H21 -> 17.970698
C23: Ending cash ($m) | D23: =D20-D21 -> 0.25518188 | E23: =E20-E21 -> 1.0638329 | F23: =F20-F21 -> 1.6908443 | G23: =G20-G21 -> 2.2455269 | H23: =H20-H21 -> 2.7543813
C24: Net debt at year-end ($m) | D24: =D22-D23 -> 52.179273 | E24: =E22-E23 -> 45.379123 | F24: =F22-F23 -> 36.879579 | G24: =G22-G23 -> 26.788315 | H24: =H22-H23 -> 15.216317
C27: Debt and cash definitions
C28: Ending gross debt equals opening debt less mandatory amortization and cash sweep. Ending cash equals opening cash plus cash flow before debt service, less mandatory amortization and cash sweep. Net debt equals gross debt less cash.

Sheet Returns
C2: Entry-to-exit sponsor returns
C3: One selected scenario. Annual dated cash flows in USD millions. Returns are formula-driven and illustrative.
C5: Selected case | D5: =Controls!D6 -> Base
C7: Cash flow date | D7: 46022 | E7: 46387 | F7: 46752 | G7: 47118 | H7: 47483 | I7: 47848
C8: Sponsor cash flow ($m) | D8: =-D16 -> -86.8 | E8: =Controls!$D$33 -> 0 | F8: =Controls!$D$33 -> 0 | G8: =Controls!$D$33 -> 0 | H8: =Controls!$D$33 -> 0 | I8: =D23 -> 210.09413
C11: Entry EBITDA ($m) | D11: ='Historical & Baseline'!F8 -> 14
C12: Entry EBITDA multiple | D12: =Controls!$D$21 -> 10
C13: Entry enterprise value ($m) | D13: =D11*D12 -> 140
C14: Entry transaction fees ($m) | D14: =D13*Controls!$D$23 -> 2.8
C15: Senior debt at entry ($m) | D15: =D11*Controls!$D$22 -> 56
C16: Sponsor equity at entry ($m) | D16: =D13+D14-D15 -> 86.8
C18: Exit EBITDA ($m) | D18: ='Operating Model'!H35 -> 22.758631
C19: Exit EBITDA multiple | D19: =INDEX(Controls!$J$15:$J$17,MATCH(Controls!$D$6,Controls!$C$15:$C$17,0)) -> 10
C20: Exit enterprise value ($m) | D20: =D18*D19 -> 227.58631
C21: Exit fees ($m) | D21: =D20*Controls!$D$24 -> 2.2758631
C22: Exit gross debt ($m) | D22: ='Cash Flow & Debt'!H22 -> 17.970698
C23: Exit equity proceeds ($m) | D23: =D20-D21-D22+'Cash Flow & Debt'!H23 -> 210.09413
C25: Sponsor MOIC | D25: =D23/D16 -> 2.4204393
C26: Sponsor IRR from dated cash flows | D26: =XIRR(D8:I8,D7:I7) -> 0.19326469
C29: Returns calculation notes
C30: Entry enterprise value = FY2025 EBITDA × entry EBITDA multiple.

Sheet Sensitivity
C2: Returns sensitivity
C3: Formula grids. The first grid holds selected-case net debt constant. The second recomputes operating cash, debt paydown, and retained cash for each AI realization input. USD millions.
C5: Selected case | D5: =Controls!D6 -> Base
C7: Exit multiple × exit EBITDA, MOIC (selected-case net debt held fixed)
C8: Direction: MOIC rises left to right with exit multiple and top to bottom with exit EBITDA.
C9: Exit EBITDA ($m) | D9: 8 | E9: 9 | F9: 10 | G9: 11 | H9: 12 | J9: Exit EBITDA factor
C10: =Returns!$D$18*$J10 -> 19.344836 | D10: =(($C10*D$9)*(1-Controls!$D$24)-Returns!$D$22+'Cash Flow & Debt'!$H$23)/Returns!$D$16 -> 1.5898017 | E10: =(($C10*E$9)*(1-Controls!$D$24)-Returns!$D$22+'Cash Flow & Debt'!$H$23)/Returns!$D$16 -> 1.8104398 | F10: =(($C10*F$9)*(1-Controls!$D$24)-Returns!$D$22+'Cash Flow & Debt'!$H$23)/Returns!$D$16 -> 2.0310779 | G10: =(($C10*G$9)*(1-Controls!$D$24)-Returns!$D$22+'Cash Flow & Debt'!$H$23)/Returns!$D$16 -> 2.251716 | H10: =(($C10*H$9)*(1-Controls!$D$24)-Returns!$D$22+'Cash Flow & Debt'!$H$23)/Returns!$D$16 -> 2.4723541 | J10: 0.85
C11: =Returns!$D$18*$J11 -> 21.051734 | D11: =(($C11*D$9)*(1-Controls!$D$24)-Returns!$D$22+'Cash Flow & Debt'!$H$23)/Returns!$D$16 -> 1.7455462 | E11: =(($C11*E$9)*(1-Controls!$D$24)-Returns!$D$22+'Cash Flow & Debt'!$H$23)/Returns!$D$16 -> 1.9856524 | F11: =(($C11*F$9)*(1-Controls!$D$24)-Returns!$D$22+'Cash Flow & Debt'!$H$23)/Returns!$D$16 -> 2.2257586 | G11: =(($C11*G$9)*(1-Controls!$D$24)-Returns!$D$22+'Cash Flow & Debt'!$H$23)/Returns!$D$16 -> 2.4658648 | H11: =(($C11*H$9)*(1-Controls!$D$24)-Returns!$D$22+'Cash Flow & Debt'!$H$23)/Returns!$D$16 -> 2.7059709 | J11: 0.925
C12: =Returns!$D$18*$J12 -> 22.758631 | D12: =(($C12*D$9)*(1-Controls!$D$24)-Returns!$D$22+'Cash Flow & Debt'!$H$23)/Returns!$D$16 -> 1.9012908 | E12: =(($C12*E$9)*(1-Controls!$D$24)-Returns!$D$22+'Cash Flow & Debt'!$H$23)/Returns!$D$16 -> 2.160865 | F12: =(($C12*F$9)*(1-Controls!$D$24)-Returns!$D$22+'Cash Flow & Debt'!$H$23)/Returns!$D$16 -> 2.4204393 | G12: =(($C12*G$9)*(1-Controls!$D$24)-Returns!$D$22+'Cash Flow & Debt'!$H$23)/Returns!$D$16 -> 2.6800135 | H12: =(($C12*H$9)*(1-Controls!$D$24)-Returns!$D$22+'Cash Flow & Debt'!$H$23)/Returns!$D$16 -> 2.9395878 | J12: 1
C13: =Returns!$D$18*$J13 -> 24.465528 | D13: =(($C13*D$9)*(1-Controls!$D$24)-Returns!$D$22+'Cash Flow & Debt'!$H$23)/Returns!$D$16 -> 2.0570353 | E13: =(($C13*E$9)*(1-Controls!$D$24)-Returns!$D$22+'Cash Flow & Debt'!$H$23)/Returns!$D$16 -> 2.3360776 | F13: =(($C13*F$9)*(1-Controls!$D$24)-Returns!$D$22+'Cash Flow & Debt'!$H$23)/Returns!$D$16 -> 2.6151199 | G13: =(($C13*G$9)*(1-Controls!$D$24)-Returns!$D$22+'Cash Flow & Debt'!$H$23)/Returns!$D$16 -> 2.8941623 | H13: =(($C13*H$9)*(1-Controls!$D$24)-Returns!$D$22+'Cash Flow & Debt'!$H$23)/Returns!$D$16 -> 3.1732046 | J13: 1.075
C14: =Returns!$D$18*$J14 -> 26.172425 | D14: =(($C14*D$9)*(1-Controls!$D$24)-Returns!$D$22+'Cash Flow & Debt'!$H$23)/Returns!$D$16 -> 2.2127799 | E14: =(($C14*E$9)*(1-Controls!$D$24)-Returns!$D$22+'Cash Flow & Debt'!$H$23)/Returns!$D$16 -> 2.5112903 | F14: =(($C14*F$9)*(1-Controls!$D$24)-Returns!$D$22+'Cash Flow & Debt'!$H$23)/Returns!$D$16 -> 2.8098006 | G14: =(($C14*G$9)*(1-Controls!$D$24)-Returns!$D$22+'Cash Flow & Debt'!$H$23)/Returns!$D$16 -> 3.108311 | H14: =(($C14*H$9)*(1-Controls!$D$24)-Returns!$D$22+'Cash Flow & Debt'!$H$23)/Returns!$D$16 -> 3.4068214 | J14: 1.15
C16: At each grid point, exit enterprise value equals exit EBITDA × exit multiple. Exit fees and selected-case net debt are then deducted before dividing by sponsor equity.
C20: Exit multiple × AI cost-realization assumption, MOIC
C21: Direction: MOIC rises with exit multiple and AI cost realization.
C22: Exit multiple | D22: 0.3 | E22: 0.5 | F22: 0.65 | G22: 0.8 | H22: 1
C23: 8 | D23: =(('Operating Model'!$H$35-'Operating Model'!$H$29+'Operating Model'!$H$28*$D$36)*$C23*(1-Controls!$D$24)-$I$49+$I$50)/Returns!$D$16 -> 1.8753227 | E23: =(('Operating Model'!$H$35-'Operating Model'!$H$29+'Operating Model'!$H$28*$D$52)*$C23*(1-Controls!$D$24)-$I$65+$I$66)/Returns!$D$16 -> 1.8901616 | F23: =(('Operating Model'!$H$35-'Operating Model'!$H$29+'Operating Model'!$H$28*$D$68)*$C23*(1-Controls!$D$24)-$I$81+$I$82)/Returns!$D$16 -> 1.9012908 | G23: =(('Operating Model'!$H$35-'Operating Model'!$H$29+'Operating Model'!$H$28*$D$84)*$C23*(1-Controls!$D$24)-$I$97+$I$98)/Returns!$D$16 -> 1.9124199 | H23: =(('Operating Model'!$H$35-'Operating Model'!$H$29+'Operating Model'!$H$28*$D$100)*$C23*(1-Controls!$D$24)-$I$113+$I$114)/Returns!$D$16 -> 1.9272588
C24: 9 | D24: =(('Operating Model'!$H$35-'Operating Model'!$H$29+'Operating Model'!$H$28*$D$36)*$C24*(1-Controls!$D$24)-$I$49+$I$50)/Returns!$D$16 -> 2.132543 | E24: =(('Operating Model'!$H$35-'Operating Model'!$H$29+'Operating Model'!$H$28*$D$52)*$C24*(1-Controls!$D$24)-$I$65+$I$66)/Returns!$D$16 -> 2.148727 | F24: =(('Operating Model'!$H$35-'Operating Model'!$H$29+'Operating Model'!$H$28*$D$68)*$C24*(1-Controls!$D$24)-$I$81+$I$82)/Returns!$D$16 -> 2.160865 | G24: =(('Operating Model'!$H$35-'Operating Model'!$H$29+'Operating Model'!$H$28*$D$84)*$C24*(1-Controls!$D$24)-$I$97+$I$98)/Returns!$D$16 -> 2.173003 | H24: =(('Operating Model'!$H$35-'Operating Model'!$H$29+'Operating Model'!$H$28*$D$100)*$C24*(1-Controls!$D$24)-$I$113+$I$114)/Returns!$D$16 -> 2.189187
C25: 10 | D25: =(('Operating Model'!$H$35-'Operating Model'!$H$29+'Operating Model'!$H$28*$D$36)*$C25*(1-Controls!$D$24)-$I$49+$I$50)/Returns!$D$16 -> 2.3897633 | E25: =(('Operating Model'!$H$35-'Operating Model'!$H$29+'Operating Model'!$H$28*$D$52)*$C25*(1-Controls!$D$24)-$I$65+$I$66)/Returns!$D$16 -> 2.4072924 | F25: =(('Operating Model'!$H$35-'Operating Model'!$H$29+'Operating Model'!$H$28*$D$68)*$C25*(1-Controls!$D$24)-$I$81+$I$82)/Returns!$D$16 -> 2.4204393 | G25: =(('Operating Model'!$H$35-'Operating Model'!$H$29+'Operating Model'!$H$28*$D$84)*$C25*(1-Controls!$D$24)-$I$97+$I$98)/Returns!$D$16 -> 2.4335861 | H25: =(('Operating Model'!$H$35-'Operating Model'!$H$29+'Operating Model'!$H$28*$D$100)*$C25*(1-Controls!$D$24)-$I$113+$I$114)/Returns!$D$16 -> 2.4511152
C26: 11 | D26: =(('Operating Model'!$H$35-'Operating Model'!$H$29+'Operating Model'!$H$28*$D$36)*$C26*(1-Controls!$D$24)-$I$49+$I$50)/Returns!$D$16 -> 2.6469836 | E26: =(('Operating Model'!$H$35-'Operating Model'!$H$29+'Operating Model'!$H$28*$D$52)*$C26*(1-Controls!$D$24)-$I$65+$I$66)/Returns!$D$16 -> 2.6658578 | F26: =(('Operating Model'!$H$35-'Operating Model'!$H$29+'Operating Model'!$H$28*$D$68)*$C26*(1-Controls!$D$24)-$I$81+$I$82)/Returns!$D$16 -> 2.6800135 | G26: =(('Operating Model'!$H$35-'Operating Model'!$H$29+'Operating Model'!$H$28*$D$84)*$C26*(1-Controls!$D$24)-$I$97+$I$98)/Returns!$D$16 -> 2.6941692 | H26: =(('Operating Model'!$H$35-'Operating Model'!$H$29+'Operating Model'!$H$28*$D$100)*$C26*(1-Controls!$D$24)-$I$113+$I$114)/Returns!$D$16 -> 2.7130434
C27: 12 | D27: =(('Operating Model'!$H$35-'Operating Model'!$H$29+'Operating Model'!$H$28*$D$36)*$C27*(1-Controls!$D$24)-$I$49+$I$50)/Returns!$D$16 -> 2.9042039 | E27: =(('Operating Model'!$H$35-'Operating Model'!$H$29+'Operating Model'!$H$28*$D$52)*$C27*(1-Controls!$D$24)-$I$65+$I$66)/Returns!$D$16 -> 2.9244232 | F27: =(('Operating Model'!$H$35-'Operating Model'!$H$29+'Operating Model'!$H$28*$D$68)*$C27*(1-Controls!$D$24)-$I$81+$I$82)/Returns!$D$16 -> 2.9395878 | G27: =(('Operating Model'!$H$35-'Operating Model'!$H$29+'Operating Model'!$H$28*$D$84)*$C27*(1-Controls!$D$24)-$I$97+$I$98)/Returns!$D$16 -> 2.9547523 | H27: =(('Operating Model'!$H$35-'Operating Model'!$H$29+'Operating Model'!$H$28*$D$100)*$C27*(1-Controls!$D$24)-$I$113+$I$114)/Returns!$D$16 -> 2.9749716
C29: This grid changes only AI cost realization. It recalculates annual taxes, cash flow, mandatory amortization, cash sweep, ending debt, and retained cash at each realization point. Other initiative assumptions stay at the selected case. The 65% column and 10.0x row are the selected Base assumptions.
C31: AI realization sensitivity calculation detail
C33: AI cost realization
C34: Synthetic axis values
C36: AI realization case 1 | D36: 0.3 | E36: 1 | F36: 2 | G36: 3 | H36: 4 | I36: 5
C37: Adjusted total EBITDA ($m) | E37: ='Operating Model'!D35-'Operating Model'!D29+'Operating Model'!D28*$D36 -> 14.07364 | F37: ='Operating Model'!E35-'Operating Model'!E29+'Operating Model'!E28*$D36 -> 17.896308 | G37: ='Operating Model'!F35-'Operating Model'!F29+'Operating Model'!F28*$D36 -> 19.75354 | H37: ='Operating Model'!G35-'Operating Model'!G29+'Operating Model'!G28*$D36 -> 21.305094 | I37: ='Operating Model'!H35-'Operating Model'!H29+'Operating Model'!H28*$D36 -> 22.552243
C38: Depreciation ($m) | E38: ='Operating Model'!D9*Controls!$D$27 -> 2.65 | F38: ='Operating Model'!E9*Controls!$D$27 -> 2.809 | G38: ='Operating Model'!F9*Controls!$D$27 -> 2.963495 | H38: ='Operating Model'!G9*Controls!$D$27 -> 3.1116697 | I38: ='Operating Model'!H9*Controls!$D$27 -> 3.2516949
C39: Interest ($m) | E39: =Returns!$D$15*Controls!$D$26 -> 5.04 | F39: =E49*Controls!$D$26 -> 4.7220032 | G39: =F49*Controls!$D$26 -> 4.190026 | H39: =G49*Controls!$D$26 -> 3.4925338 | I39: =H49*Controls!$D$26 -> 2.6479414
C40: Cash taxes ($m) | E40: =MAX(0,E37-E38-E39)*Controls!$D$25 -> 1.59591 | F40: =MAX(0,F37-F38-F39)*Controls!$D$25 -> 2.5913262 | G40: =MAX(0,G37-G38-G39)*Controls!$D$25 -> 3.1500049 | H40: =MAX(0,H37-H38-H39)*Controls!$D$25 -> 3.6752227 | I40: =MAX(0,I37-I38-I39)*Controls!$D$25 -> 4.1631516
C41: Capital expenditure ($m) | E41: ='Operating Model'!D9*Controls!$D$28 -> 3.18 | F41: ='Operating Model'!E9*Controls!$D$28 -> 3.3708 | G41: ='Operating Model'!F9*Controls!$D$28 -> 3.556194 | H41: ='Operating Model'!G9*Controls!$D$28 -> 3.7340037 | I41: ='Operating Model'!H9*Controls!$D$28 -> 3.9020339
C42: Working capital investment ($m) | E42: =MAX(0,('Operating Model'!D9-'Historical & Baseline'!$F$7)*Controls!$D$29) -> 0.48 | F42: =MAX(0,('Operating Model'!E9-'Operating Model'!D9)*Controls!$D$29) -> 0.5088 | G42: =MAX(0,('Operating Model'!F9-'Operating Model'!E9)*Controls!$D$29) -> 0.494384 | H42: =MAX(0,('Operating Model'!G9-'Operating Model'!F9)*Controls!$D$29) -> 0.4741592 | I42: =MAX(0,('Operating Model'!H9-'Operating Model'!G9)*Controls!$D$29) -> 0.44808044
C43: Cash flow before debt service ($m) | E43: =E37-E40-E39-E41-E42 -> 3.77773 | F43: =F37-F40-F39-F41-F42 -> 6.7033786 | G43: =G37-G40-G39-G41-G42 -> 8.3629316 | H43: =H37-H40-H39-H41-H42 -> 9.9291751 | I43: =I37-I40-I39-I41-I42 -> 11.391035
C44: Opening debt ($m) | E44: =Returns!$D$15 -> 56 | F44: =E49 -> 52.466702 | G44: =F49 -> 46.555844 | H44: =G49 -> 38.805931 | I44: =H49 -> 29.421571
C45: Opening cash ($m) | E45: =Controls!$D$33 -> 0 | F45: =E50 -> 0.2444325 | G45: =F50 -> 1.0369528 | H45: =G50 -> 1.6499711 | I45: =H50 -> 2.1947865
C46: Mandatory amortization ($m) | E46: =MIN(E44,Returns!$D$15*Controls!$D$30) -> 2.8 | F46: =MIN(F44,Returns!$D$15*Controls!$D$30) -> 2.8 | G46: =MIN(G44,Returns!$D$15*Controls!$D$30) -> 2.8 | H46: =MIN(H44,Returns!$D$15*Controls!$D$30) -> 2.8 | I46: =MIN(I44,Returns!$D$15*Controls!$D$30) -> 2.8
C47: Cash available after mandatory amortization ($m) | E47: =E45+E43-E46 -> 0.97773 | F47: =F45+F43-F46 -> 4.1478111 | G47: =G45+G43-G46 -> 6.5998844 | H47: =H45+H43-H46 -> 8.7791462 | I47: =I45+I43-I46 -> 10.785822
C48: Cash sweep ($m) | E48: =MIN(E44-E46,MAX(0,E47)*Controls!$D$31) -> 0.7332975 | F48: =MIN(F44-F46,MAX(0,F47)*Controls!$D$31) -> 3.1108583 | G48: =MIN(G44-G46,MAX(0,G47)*Controls!$D$31) -> 4.9499133 | H48: =MIN(H44-H46,MAX(0,H47)*Controls!$D$31) -> 6.5843596 | I48: =MIN(I44-I46,MAX(0,I47)*Controls!$D$31) -> 8.0893665
C49: Ending gross debt ($m) | E49: =E44-E46-E48 -> 52.466702 | F49: =F44-F46-F48 -> 46.555844 | G49: =G44-G46-G48 -> 38.805931 | H49: =H44-H46-H48 -> 29.421571 | I49: =I44-I46-I48 -> 18.532205
E50: =E47-E48 -> 0.2444325 | F50: =F47-F48 -> 1.0369528 | G50: =G47-G48 -> 1.6499711 | H50: =H47-H48 -> 2.1947865 | I50: =I47-I48 -> 2.6964555
E51: =E49-E50 -> 52.22227 | F51: =F49-F50 -> 45.518891 | G51: =G49-G50 -> 37.15596 | H51: =H49-H50 -> 27.226785 | I51: =I49-I50 -> 15.835749
...

Sheet VCP Tracker
C2: Quarterly value creation plan tracker
C3: Synthetic plan and synthetic actuals illustrate ownership, execution measures, variance, RAG status, and next actions. USD unless KPI states percent.
C5: RAG thresholds: Green at or above the green variance limit; Amber between the green and amber limits; Red below the amber limit.
C6: AI Expand / Fix / Pause is a governance signal only and does not change the forecast. If adoption and quality both fail, Pause takes precedence.
C7: Initiative | D7: Quarter | E7: Owner role | F7: KPI | G7: Plan | H7: Synthetic actual | I7: Variance (actual less plan) | J7: RAG | K7: Quality KPI | L7: AI gate | M7: Next action | N7: Quarter phasing | O7: Synthetic actual input | P7: Year index | Q7: RAG threshold note
C8: Pricing and mix | D8: 2026 Q1 | E8: Commercial workstream owner (synthetic role) | F8: Renewal adoption (% of eligible renewals) | G8: =Initiatives!K7*N8 -> 0.075 | H8: =G8*O8 -> 0.07065 | I8: =H8-G8 -> -0.00435 | J8: =IF(I8>=Controls!$D$37,"Green",IF(I8>=Controls!$D$38,"Amber","Red")) -> Green | K8: n.a. | L8: n.a. | M8: Review adoption barrier and next renewal cohort | N8: 0.25 | O8: 0.942 | P8: 1 | Q8: Synthetic plan and sample tracking; not measured company results
C9: Pricing and mix | D9: 2026 Q2 | E9: Commercial workstream owner (synthetic role) | F9: Renewal adoption (% of eligible renewals) | G9: =Initiatives!K7*N9 -> 0.15 | H9: =G9*O9 -> 0.14775 | I9: =H9-G9 -> -0.00225 | J9: =IF(I9>=Controls!$D$37,"Green",IF(I9>=Controls!$D$38,"Amber","Red")) -> Green | K9: n.a. | L9: n.a. | M9: Review adoption barrier and next renewal cohort | N9: 0.5 | O9: 0.985 | P9: 1 | Q9: Synthetic plan and sample tracking; not measured company results
C10: Pricing and mix | D10: 2026 Q3 | E10: Commercial workstream owner (synthetic role) | F10: Renewal adoption (% of eligible renewals) | G10: =Initiatives!K7*N10 -> 0.225 | H10: =G10*O10 -> 0.22725 | I10: =H10-G10 -> 0.00225 | J10: =IF(I10>=Controls!$D$37,"Green",IF(I10>=Controls!$D$38,"Amber","Red")) -> Green | K10: n.a. | L10: n.a. | M10: Review adoption barrier and next renewal cohort | N10: 0.75 | O10: 1.01 | P10: 1 | Q10: Synthetic plan and sample tracking; not measured company results
C11: Pricing and mix | D11: 2026 Q4 | E11: Commercial workstream owner (synthetic role) | F11: Renewal adoption (% of eligible renewals) | G11: =Initiatives!K7*N11 -> 0.3 | H11: =G11*O11 -> 0.273 | I11: =H11-G11 -> -0.027 | J11: =IF(I11>=Controls!$D$37,"Green",IF(I11>=Controls!$D$38,"Amber","Red")) -> Green | K11: n.a. | L11: n.a. | M11: Review adoption barrier and next renewal cohort | N11: 1 | O11: 0.91 | P11: 1 | Q11: Synthetic plan and sample tracking; not measured company results
C12: Pricing and mix | D12: 2027 Q1 | E12: Commercial workstream owner (synthetic role) | F12: Renewal adoption (% of eligible renewals) | G12: =Initiatives!K7+(Initiatives!L7-Initiatives!K7)*N12 -> 0.3875 | H12: =G12*O12 -> 0.3747125 | I12: =H12-G12 -> -0.0127875 | J12: =IF(I12>=Controls!$D$37,"Green",IF(I12>=Controls!$D$38,"Amber","Red")) -> Green | K12: n.a. | L12: n.a. | M12: Review adoption barrier and next renewal cohort | N12: 0.25 | O12: 0.967 | P12: 2 | Q12: Synthetic plan and sample tracking; not measured company results
C13: Pricing and mix | D13: 2027 Q2 | E13: Commercial workstream owner (synthetic role) | F13: Renewal adoption (% of eligible renewals) | G13: =Initiatives!K7+(Initiatives!L7-Initiatives!K7)*N13 -> 0.475 | H13: =G13*O13 -> 0.47975 | I13: =H13-G13 -> 0.00475 | J13: =IF(I13>=Controls!$D$37,"Green",IF(I13>=Controls!$D$38,"Amber","Red")) -> Green | K13: n.a. | L13: n.a. | M13: Review adoption barrier and next renewal cohort | N13: 0.5 | O13: 1.01 | P13: 2 | Q13: Synthetic plan and sample tracking; not measured company results
C14: Pricing and mix | D14: 2027 Q3 | E14: Commercial workstream owner (synthetic role) | F14: Renewal adoption (% of eligible renewals) | G14: =Initiatives!K7+(Initiatives!L7-Initiatives!K7)*N14 -> 0.5625 | H14: =G14*O14 -> 0.511875 | I14: =H14-G14 -> -0.050625 | J14: =IF(I14>=Controls!$D$37,"Green",IF(I14>=Controls!$D$38,"Amber","Red")) -> Amber | K14: n.a. | L14: n.a. | M14: Review adoption barrier and next renewal cohort | N14: 0.75 | O14: 0.91 | P14: 2 | Q14: Synthetic plan and sample tracking; not measured company results
C15: Pricing and mix | D15: 2027 Q4 | E15: Commercial workstream owner (synthetic role) | F15: Renewal adoption (% of eligible renewals) | G15: =Initiatives!K7+(Initiatives!L7-Initiatives!K7)*N15 -> 0.65 | H15: =G15*O15 -> 0.60775 | I15: =H15-G15 -> -0.04225 | J15: =IF(I15>=Controls!$D$37,"Green",IF(I15>=Controls!$D$38,"Amber","Red")) -> Green | K15: n.a. | L15: n.a. | M15: Review adoption barrier and next renewal cohort | N15: 1 | O15: 0.935 | P15: 2 | Q15: Synthetic plan and sample tracking; not measured company results
C16: Pricing and mix | D16: 2028 Q1 | E16: Commercial workstream owner (synthetic role) | F16: Renewal adoption (% of eligible renewals) | G16: =Initiatives!L7+(Initiatives!M7-Initiatives!L7)*N16 -> 0.7 | H16: =G16*O16 -> 0.6944 | I16: =H16-G16 -> -0.0056 | J16: =IF(I16>=Controls!$D$37,"Green",IF(I16>=Controls!$D$38,"Amber","Red")) -> Green | K16: n.a. | L16: n.a. | M16: Review adoption barrier and next renewal cohort | N16: 0.25 | O16: 0.992 | P16: 3 | Q16: Synthetic plan and sample tracking; not measured company results
C17: Pricing and mix | D17: 2028 Q2 | E17: Commercial workstream owner (synthetic role) | F17: Renewal adoption (% of eligible renewals) | G17: =Initiatives!L7+(Initiatives!M7-Initiatives!L7)*N17 -> 0.75 | H17: =G17*O17 -> 0.6825 | I17: =H17-G17 -> -0.0675 | J17: =IF(I17>=Controls!$D$37,"Green",IF(I17>=Controls!$D$38,"Amber","Red")) -> Amber | K17: n.a. | L17: n.a. | M17: Review adoption barrier and next renewal cohort | N17: 0.5 | O17: 0.91 | P17: 3 | Q17: Synthetic plan and sample tracking; not measured company results
C18: Pricing and mix | D18: 2028 Q3 | E18: Commercial workstream owner (synthetic role) | F18: Renewal adoption (% of eligible renewals) | G18: =Initiatives!L7+(Initiatives!M7-Initiatives!L7)*N18 -> 0.8 | H18: =G18*O18 -> 0.748 | I18: =H18-G18 -> -0.052 | J18: =IF(I18>=Controls!$D$37,"Green",IF(I18>=Controls!$D$38,"Amber","Red")) -> Amber | K18: n.a. | L18: n.a. | M18: Review adoption barrier and next renewal cohort | N18: 0.75 | O18: 0.935 | P18: 3 | Q18: Synthetic plan and sample tracking; not measured company results
C19: Pricing and mix | D19: 2028 Q4 | E19: Commercial workstream owner (synthetic role) | F19: Renewal adoption (% of eligible renewals) | G19: =Initiatives!L7+(Initiatives!M7-Initiatives!L7)*N19 -> 0.85 | H19: =G19*O19 -> 0.816 | I19: =H19-G19 -> -0.034 | J19: =IF(I19>=Controls!$D$37,"Green",IF(I19>=Controls!$D$38,"Amber","Red")) -> Green | K19: n.a. | L19: n.a. | M19: Review adoption barrier and next renewal cohort | N19: 1 | O19: 0.96 | P19: 3 | Q19: Synthetic plan and sample tracking; not measured company results
C20: Pricing and mix | D20: 2029 Q1 | E20: Commercial workstream owner (synthetic role) | F20: Renewal adoption (% of eligible renewals) | G20: =Initiatives!M7+(Initiatives!N7-Initiatives!M7)*N20 -> 0.875 | H20: =G20*O20 -> 0.7805 | I20: =H20-G20 -> -0.0945 | J20: =IF(I20>=Controls!$D$37,"Green",IF(I20>=Controls!$D$38,"Amber","Red")) -> Amber | K20: n.a. | L20: n.a. | M20: Review adoption barrier and next renewal cohort | N20: 0.25 | O20: 0.892 | P20: 4 | Q20: Synthetic plan and sample tracking; not measured company results
C21: Pricing and mix | D21: 2029 Q2 | E21: Commercial workstream owner (synthetic role) | F21: Renewal adoption (% of eligible renewals) | G21: =Initiatives!M7+(Initiatives!N7-Initiatives!M7)*N21 -> 0.9 | H21: =G21*O21 -> 0.8415 | I21: =H21-G21 -> -0.0585 | J21: =IF(I21>=Controls!$D$37,"Green",IF(I21>=Controls!$D$38,"Amber","Red")) -> Amber | K21: n.a. | L21: n.a. | M21: Review adoption barrier and next renewal cohort | N21: 0.5 | O21: 0.935 | P21: 4 | Q21: Synthetic plan and sample tracking; not measured company results
C22: Pricing and mix | D22: 2029 Q3 | E22: Commercial workstream owner (synthetic role) | F22: Renewal adoption (% of eligible renewals) | G22: =Initiatives!M7+(Initiatives!N7-Initiatives!M7)*N22 -> 0.925 | H22: =G22*O22 -> 0.888 | I22: =H22-G22 -> -0.037 | J22: =IF(I22>=Controls!$D$37,"Green",IF(I22>=Controls!$D$38,"Amber","Red")) -> Green | K22: n.a. | L22: n.a. | M22: Review adoption barrier and next renewal cohort | N22: 0.75 | O22: 0.96 | P22: 4 | Q22: Synthetic plan and sample tracking; not measured company results
C23: Pricing and mix | D23: 2029 Q4 | E23: Commercial workstream owner (synthetic role) | F23: Renewal adoption (% of eligible renewals) | G23: =Initiatives!M7+(Initiatives!N7-Initiatives!M7)*N23 -> 0.95 | H23: =G23*O23 -> 0.93575 | I23: =H23-G23 -> -0.01425 | J23: =IF(I23>=Controls!$D$37,"Green",IF(I23>=Controls!$D$38,"Amber","Red")) -> Green | K23: n.a. | L23: n.a. | M23: Review adoption barrier and next renewal cohort | N23: 1 | O23: 0.985 | P23: 4 | Q23: Synthetic plan and sample tracking; not measured company results
C24: Pricing and mix | D24: 2030 Q1 | E24: Commercial workstream owner (synthetic role) | F24: Renewal adoption (% of eligible renewals) | G24: =Initiatives!N7+(Initiatives!O7-Initiatives!N7)*N24 -> 0.9625 | H24: =G24*O24 -> 0.8826125 | I24: =H24-G24 -> -0.0798875 | J24: =IF(I24>=Controls!$D$37,"Green",IF(I24>=Controls!$D$38,"Amber","Red")) -> Amber | K24: n.a. | L24: n.a. | M24: Review adoption barrier and next renewal cohort | N24: 0.25 | O24: 0.917 | P24: 5 | Q24: Synthetic plan and sample tracking; not measured company results
C25: Pricing and mix | D25: 2030 Q2 | E25: Commercial workstream owner (synthetic role) | F25: Renewal adoption (% of eligible renewals) | G25: =Initiatives!N7+(Initiatives!O7-Initiatives!N7)*N25 -> 0.975 | H25: =G25*O25 -> 0.936 | I25: =H25-G25 -> -0.039 | J25: =IF(I25>=Controls!$D$37,"Green",IF(I25>=Controls!$D$38,"Amber","Red")) -> Green | K25: n.a. | L25: n.a. | M25: Review adoption barrier and next renewal cohort | N25: 0.5 | O25: 0.96 | P25: 5 | Q25: Synthetic plan and sample tracking; not measured company results
C26: Pricing and mix | D26: 2030 Q3 | E26: Commercial workstream owner (synthetic role) | F26: Renewal adoption (% of eligible renewals) | G26: =Initiatives!N7+(Initiatives!O7-Initiatives!N7)*N26 -> 0.9875 | H26: =G26*O26 -> 0.9726875 | I26: =H26-G26 -> -0.0148125 | J26: =IF(I26>=Controls!$D$37,"Green",IF(I26>=Controls!$D$38,"Amber","Red")) -> Green | K26: n.a. | L26: n.a. | M26: Review adoption barrier and next renewal cohort | N26: 0.75 | O26: 0.985 | P26: 5 | Q26: Synthetic plan and sample tracking; not measured company results
C27: Pricing and mix | D27: 2030 Q4 | E27: Commercial workstream owner (synthetic role) | F27: Renewal adoption (% of eligible renewals) | G27: =Initiatives!N7+(Initiatives!O7-Initiatives!N7)*N27 -> 1 | H27: =G27*O27 -> 1.01 | I27: =H27-G27 -> 0.01 | J27: =IF(I27>=Controls!$D$37,"Green",IF(I27>=Controls!$D$38,"Amber","Red")) -> Green | K27: n.a. | L27: n.a. | M27: Review adoption barrier and next renewal cohort | N27: 1 | O27: 1.01 | P27: 5 | Q27: Synthetic plan and sample tracking; not measured company results
C28: Commercial efficiency | D28: 2026 Q1 | E28: Operations workstream owner (synthetic role) | F28: Savings delivered (% of run-rate target) | G28: =Initiatives!K14*N28 -> 0.0625 | H28: =G28*O28 -> 0.058875 | I28: =H28-G28 -> -0.003625 | J28: =IF(I28>=Controls!$D$37,"Green",IF(I28>=Controls!$D$38,"Amber","Red")) -> Green | K28: n.a. | L28: n.a. | M28: Confirm validated savings and service guardrails | N28: 0.25 | O28: 0.942 | P28: 1 | Q28: Synthetic plan and sample tracking; not measured company results
C29: Commercial efficiency | D29: 2026 Q2 | E29: Operations workstream owner (synthetic role) | F29: Savings delivered (% of run-rate target) | G29: =Initiatives!K14*N29 -> 0.125 | H29: =G29*O29 -> 0.123125 | I29: =H29-G29 -> -0.001875 | J29: =IF(I29>=Controls!$D$37,"Green",IF(I29>=Controls!$D$38,"Amber","Red")) -> Green | K29: n.a. | L29: n.a. | M29: Confirm validated savings and service guardrails | N29: 0.5 | O29: 0.985 | P29: 1 | Q29: Synthetic plan and sample tracking; not measured company results
C30: Commercial efficiency | D30: 2026 Q3 | E30: Operations workstream owner (synthetic role) | F30: Savings delivered (% of run-rate target) | G30: =Initiatives!K14*N30 -> 0.1875 | H30: =G30*O30 -> 0.189375 | I30: =H30-G30 -> 0.001875 | J30: =IF(I30>=Controls!$D$37,"Green",IF(I30>=Controls!$D$38,"Amber","Red")) -> Green | K30: n.a. | L30: n.a. | M30: Confirm validated savings and service guardrails | N30: 0.75 | O30: 1.01 | P30: 1 | Q30: Synthetic plan and sample tracking; not measured company results
C31: Commercial efficiency | D31: 2026 Q4 | E31: Operations workstream owner (synthetic role) | F31: Savings delivered (% of run-rate target) | G31: =Initiatives!K14*N31 -> 0.25 | H31: =G31*O31 -> 0.2275 | I31: =H31-G31 -> -0.0225 | J31: =IF(I31>=Controls!$D$37,"Green",IF(I31>=Controls!$D$38,"Amber","Red")) -> Green | K31: n.a. | L31: n.a. | M31: Confirm validated savings and service guardrails | N31: 1 | O31: 0.91 | P31: 1 | Q31: Synthetic plan and sample tracking; not measured company results
C32: Commercial efficiency | D32: 2027 Q1 | E32: Operations workstream owner (synthetic role) | F32: Savings delivered (% of run-rate target) | G32: =Initiatives!K14+(Initiatives!L14-Initiatives!K14)*N32 -> 0.3375 | H32: =G32*O32 -> 0.3263625 | I32: =H32-G32 -> -0.0111375 | J32: =IF(I32>=Controls!$D$37,"Green",IF(I32>=Controls!$D$38,"Amber","Red")) -> Green | K32: n.a. | L32: n.a. | M32: Confirm validated savings and service guardrails | N32: 0.25 | O32: 0.967 | P32: 2 | Q32: Synthetic plan and sample tracking; not measured company results
C33: Commercial efficiency | D33: 2027 Q2 | E33: Operations workstream owner (synthetic role) | F33: Savings delivered (% of run-rate target) | G33: =Initiatives!K14+(Initiatives!L14-Initiatives!K14)*N33 -> 0.425 | H33: =G33*O33 -> 0.42925 | I33: =H33-G33 -> 0.00425 | J33: =IF(I33>=Controls!$D$37,"Green",IF(I33>=Controls!$D$38,"Amber","Red")) -> Green | K33: n.a. | L33: n.a. | M33: Confirm validated savings and service guardrails | N33: 0.5 | O33: 1.01 | P33: 2 | Q33: Synthetic plan and sample tracking; not measured company results
C34: Commercial efficiency | D34: 2027 Q3 | E34: Operations workstream owner (synthetic role) | F34: Savings delivered (% of run-rate target) | G34: =Initiatives!K14+(Initiatives!L14-Initiatives!K14)*N34 -> 0.5125 | H34: =G34*O34 -> 0.466375 | I34: =H34-G34 -> -0.046125 | J34: =IF(I34>=Controls!$D$37,"Green",IF(I34>=Controls!$D$38,"Amber","Red")) -> Green | K34: n.a. | L34: n.a. | M34: Confirm validated savings and service guardrails | N34: 0.75 | O34: 0.91 | P34: 2 | Q34: Synthetic plan and sample tracking; not measured company results
C35: Commercial efficiency | D35: 2027 Q4 | E35: Operations workstream owner (synthetic role) | F35: Savings delivered (% of run-rate target) | G35: =Initiatives!K14+(Initiatives!L14-Initiatives!K14)*N35 -> 0.6 | H35: =G35*O35 -> 0.561 | I35: =H35-G35 -> -0.039 | J35: =IF(I35>=Controls!$D$37,"Green",IF(I35>=Controls!$D$38,"Amber","Red")) -> Green | K35: n.a. | L35: n.a. | M35: Confirm validated savings and service guardrails | N35: 1 | O35: 0.935 | P35: 2 | Q35: Synthetic plan and sample tracking; not measured company results
